Workbook

Sheet Summary
A1: OpenAI & Anthropic - 2030 revenue framework (bottom-up vs compute vs momentum)
A2: All cells are links to the company sheets (green). Edit assumptions on Inputs (Custom column).
A4: Metric ($B) | B4: Bear | C4: Base | D4: Bull | E4: Custom
A5: OpenAI - bottom-up revenue 2030 | B5: =OpenAI!C27 -> 95.810644 | C5: =OpenAI!D27 -> 297.655 | D5: =OpenAI!E27 -> 714.324 | E5: =OpenAI!F27 -> 297.655
A6: OpenAI - supply-side capacity 2030 | B6: =OpenAI!C36 -> 95.04 | C6: =OpenAI!D36 -> 296.8064 | D6: =OpenAI!E36 -> 1401.7536 | E6: =OpenAI!F36 -> 296.8064
A7: OpenAI - momentum exit-2030 run-rate | B7: =OpenAI!C47 -> 116.53824 | C7: =OpenAI!D47 -> 274.05 | D7: =OpenAI!E47 -> 407.28188 | E7: =OpenAI!F47 -> 274.05
A8: OpenAI - $/GW needed for bottom-up | B8: =OpenAI!C40 -> 6.3873763 | C8: =OpenAI!D40 -> 13.529773 | D8: =OpenAI!E40 -> 23.8108 | E8: =OpenAI!F40 -> 13.529773
A9: Anthropic - bottom-up revenue 2030 | B9: =Anthropic!C27 -> 82.332124 | C9: =Anthropic!D27 -> 259.416 | D9: =Anthropic!E27 -> 567.71136 | E9: =Anthropic!F27 -> 259.416
A10: Anthropic - supply-side capacity 2030 | B10: =Anthropic!C36 -> 63.36 | C10: =Anthropic!D36 -> 215.8592 | D10: =Anthropic!E36 -> 1027.9526 | E10: =Anthropic!F36 -> 215.8592
A11: Anthropic - momentum exit-2030 run-rate | B11: =Anthropic!C47 -> 162.21901 | C11: =Anthropic!D47 -> 346.086 | D11: =Anthropic!E47 -> 582.4 | E11: =Anthropic!F47 -> 346.086
A12: Anthropic - $/GW needed for bottom-up | B12: =Anthropic!C40 -> 8.2332124 | C12: =Anthropic!D40 -> 16.2135 | D12: =Anthropic!E40 -> 25.805062 | E12: =Anthropic!F40 -> 16.2135
A13: Combined bottom-up revenue 2030 | B13: =B5+B9 -> 178.14277 | C13: =C5+C9 -> 557.071 | D13: =D5+D9 -> 1282.0354 | E13: =E5+E9 -> 557.071
A15: Reference points (2026)
A16: OpenAI run-rate Aug-2026 | B16: 40 | C16: press reports; enterprise >50% of mix
A17: Anthropic run-rate end-Jul-2026 | B17: 65 | C17: Bloomberg/Axios 17-Aug-2026
A18: OpenAI company plan 2030 | B18: 280 | C18: >$280B (Bloomberg 20-Feb-2026); later reports up to ~$350B
A19: Anthropic company plan 2028 | B19: 195 | C19: $190-200B (Reuters 14-Aug-2026)
A20: Superforecaster median, OpenAI+Anthropic combined 2030 run-rate | B20: 300 | C20: Forecasting Research Institute; 34% prob. >$400B
A21: Bain: AI revenue needed by 2030 (whole industry) | B21: 2000 | C21: Bain Global Technology Report 2025

Sheet Inputs
A1: Inputs - 2030 assumptions (bear / base / bull) + Custom scenario
A2: Legend: blue = hardcoded input; yellow Custom column (G) is the one to edit - it defaults to Base. All formulas on the other sheets read this sheet. Anchors are 2026 observed data points (see Sources).
A4: Key | B4: Assumption (2030 unless stated) | C4: Unit | D4: Bear | E4: Base | F4: Bull | G4: Custom (edit) | H4: 2026 anchor / rationale
A5: Pool
A6: kw_dev | B6: Developers / data-AI engineers (M) | C6: M people | D6: 34 | E6: 38 | F6: 44 | G6: 38 | H6: ~30M professional devs 2026 (SlashData/Evans est.); AI-native builders expand the pool
A7: kw_pro | B7: Professional / high-intensity knowledge workers (M) | C7: M people | D7: 205 | E7: 220 | F7: 240 | G7: 220 | H7: finance, legal, consulting, research, marketing, sales, product; ~20% of ~1.05B KW
A8: kw_gen | B8: General knowledge workers (M) | C8: M people | D8: 770 | E8: 790 | F8: 815 | G8: 790 | H8: ~1B+ knowledge workers globally (Gartner >1B; Forrester 1.25B info workers); residual
A9: sal_dev | B9: Avg salary - developers ($k/yr, global blend) | C9: $k/yr | D9: 72 | E9: 75 | F9: 80 | G9: 75 | H9: US ~$150k, India ~$15k; global blend ~$75k
A10: sal_pro | B10: Avg salary - professionals ($k/yr, global blend) | C10: $k/yr | D10: 57 | E10: 60 | F10: 65 | G10: 60 | H10: global blend; US-only ~$100-120k
A11: sal_gen | B11: Avg salary - general KW ($k/yr, global blend) | C11: $k/yr | D11: 29 | E11: 30 | F11: 32 | G11: 30 | H11: global blend incl. EM
A12: Penetration
A13: pen_dev | B13: Paid-AI penetration - developers | C13: % | D13: 0.68 | E13: 0.8 | F13: 0.9 | G13: 0.8 | H13: 2026: ~10-12M paid (GitHub Copilot 4.7M, Cursor, Claude Code, Codex) of ~30M = ~35-40%
A14: pen_pro | B14: Paid-AI penetration - professionals | C14: % | D14: 0.32 | E14: 0.45 | F14: 0.55 | G14: 0.45 | H14: 2026: ~35-40M paid seats globally (M365 Copilot 20M, ChatGPT biz 9M, Claude, Gemini) = ~4% of all KW, ~10% of pros
A15: pen_gen | B15: Paid-AI penetration - general KW | C15: % | D15: 0.14 | E15: 0.25 | F15: 0.38 | G15: 0.25 | H15: seat-type products ($20-30/mo); Copilot bundling drives this
A16: Spend
A17: ratio_dev | B17: AI spend / salary - developers | C17: % | D17: 0.07 | E17: 0.13 | F17: 0.16 | G17: 0.13 | H17: 2026: Claude Code enterprise avg $150-250/mo = $1.8-3k/yr = 2-4% of global-blend salary; heavy agent users >$1k/mo
A18: ratio_pro | B18: AI spend / salary - professionals | C18: % | D18: 0.015 | E18: 0.03 | F18: 0.045 | G18: 0.03 | H18: 2026: M365 Copilot $360/yr; ChatGPT Enterprise ~$600-900/yr incl. usage; Atlanta Fed avg AI spend/employee $2,068 (all AI)
A19: ratio_gen | B19: AI spend / salary - general KW | C19: % | D19: 0.007 | E19: 0.012 | F19: 0.02 | G19: 0.012 | H19: 2026: Copilot $360/yr; ChatGPT Business $25-30/seat
A20: Share
A21: sh_dev_ant | B21: Anthropic share - developer spend | C21: % | D21: 0.35 | E21: 0.42 | F21: 0.48 | G21: 0.42 | H21: 2026: Claude Code $8B ARR (May-26) + Claude inside Cursor/Copilot; Menlo Ventures: Anthropic ~54% of coding model spend (2025)
A22: sh_dev_oai | B22: OpenAI share - developer spend | C22: % | D22: 0.18 | E22: 0.25 | F22: 0.32 | G22: 0.25 | H22: Codex 2M+ weekly users (Mar-26); GPT-5.x in Cursor/Copilot
A23: sh_pro_ant | B23: Anthropic share - professional seats | C23: % | D23: 0.13 | E23: 0.2 | F23: 0.24 | G23: 0.2 | H23: Claude Enterprise/Team/Cowork + Bedrock/Vertex/Foundry; MSFT/Google own the seat bundles
A24: sh_pro_oai | B24: OpenAI share - professional seats | C24: % | D24: 0.25 | E24: 0.3 | F24: 0.35 | G24: 0.3 | H24: 2026: 7M enterprise seats, 9M paying business users, >1M business customers
A25: sh_gen_ant | B25: Anthropic share - general seats | C25: % | D25: 0.06 | E25: 0.08 | F25: 0.12 | G25: 0.08 | H25: mostly model-layer share of Copilot-type bundles
A26: sh_gen_oai | B26: OpenAI share - general seats | C26: % | D26: 0.2 | E26: 0.25 | F26: 0.3 | G26: 0.25 | H26: ChatGPT Business/Edu; Copilot uses OpenAI models (rev share)
A27: Machine
A28: auto_pool | B28: Labour cost pool of AI-automatable digital tasks ($T) | C28: $T | D28: 7 | E28: 8 | F28: 10 | G28: 8 | H28: global labour comp ~$58T (2025); knowledge-work comp $35-50T; ~15-20% is task-automatable (support, back-office, docs, content, SDR, IT ops)
A29: auto_share | B29: Share of that pool automated by AI agents in 2030 | C29: % | D29: 0.06 | E29: 0.1 | F29: 0.14 | G29: 0.1 | H29: 2026: customer-service and coding agents are the only scaled cases
A30: auto_capture | B30: Vendor capture ($ AI spend per $ labour displaced) | C30: % | D30: 0.2 | E30: 0.25 | F30: 0.3 | G30: 0.25 | H30: Claude Code $2-3k/yr vs $20-40k of dev output = ~10%; SaaS captures 10-30% of value
A31: sh_auto_ant | B31: Anthropic share - machine API | C31: % | D31: 0.3 | E31: 0.38 | F31: 0.4 | G31: 0.38 | H31: Menlo Ventures 2025: Anthropic ~32-40% of enterprise LLM API spend, OpenAI ~25%
A32: sh_auto_oai | B32: OpenAI share - machine API | C32: % | D32: 0.2 | E32: 0.25 | F32: 0.28 | G32: 0.25 | H32: API ~15-20% of OpenAI revenue (2026); 15B tokens/min (Mar-26)
A33: Consumer OAI
A34: oai_mau | B34: ChatGPT MAU 2030 (M) | C34: M people | D34: 1500 | E34: 2000 | F34: 2500 | G34: 2000 | H34: 1B MAU (Jun-26), ~1B WAU (Jul-26); internet users ~5.6B->6B; Meta DAP 3.58B
A35: oai_conv | B35: Paid conversion (subs / MAU) | C35: % | D35: 0.045 | E35: 0.06 | F35: 0.09 | G35: 0.06 | H35: >50M consumer subs / ~1B = ~5% (Aug-26); India Go free promo dilutes
A36: oai_arpu | B36: Paid ARPU ($/month, blended) | C36: $/mo | D36: 15 | E36: 18 | F36: 24 | G36: 18 | H36: Go $8 (US)/Rs399 (India), Plus $20, Pro $200 (~0.5M subs); blended est. $25-30 in 2026, skewing down with EM mix
A37: oai_ad_arpu | B37: Ads ARPU per FREE user ($/yr) | C37: $/yr | D37: 15 | E37: 30 | F37: 55 | G37: 30 | H37: Meta ARPP 2025 $58 global (US&C ~$250+); Google Search ~$60-70/user; OpenAI plan $100B ads by 2030 = ~$50/free user; ads $1B run-rate <200 days after Feb-26 launch
A38: oai_gmv | B38: Commerce GMV routed via ChatGPT ($B) | C38: $B | D38: 100 | E38: 400 | F38: 1000 | G38: 400 | H38: Instant Checkout (Sep-25); global e-commerce ~$7T by 2030
A39: oai_take | B39: Commerce take rate | C39: % | D39: 0.02 | E39: 0.025 | F39: 0.03 | G39: 0.025 | H39: affiliate/checkout take rates 2-4%
A40: Consumer ANT
A41: ant_mau | B41: Claude consumer MAU 2030 (M) | C41: M people | D41: 150 | E41: 250 | F41: 400 | G41: 250 | H41: 2026 est. 30-140M (third-party, unreliable); consumer ~5-10% of revenue
...

Sheet OpenAI
A1: OpenAI - 2030 revenue, bottom-up ($B unless stated)
A2: Green = link to Inputs; black = formula; blue = hardcoded (2026 mix estimates, targets, constants).
A4: Line | B4: Unit | C4: Bear | D4: Base | E4: Bull | F4: Custom | G4: Formula / note
A5: Global pools (all vendors) - shared with the other company
A6: Spend per paid seat - developers | B6: $/yr | C6: =Inputs!$D$9*Inputs!$D$17*1000 -> 5040 | D6: =Inputs!$E$9*Inputs!$E$17*1000 -> 9750 | E6: =Inputs!$F$9*Inputs!$F$17*1000 -> 12800 | F6: =Inputs!$G$9*Inputs!$G$17*1000 -> 9750 | G6: salary x AI spend ratio
A7: Spend per paid seat - professionals | B7: $/yr | C7: =Inputs!$D$10*Inputs!$D$18*1000 -> 855 | D7: =Inputs!$E$10*Inputs!$E$18*1000 -> 1800 | E7: =Inputs!$F$10*Inputs!$F$18*1000 -> 2925 | F7: =Inputs!$G$10*Inputs!$G$18*1000 -> 1800
A8: Spend per paid seat - general KW | B8: $/yr | C8: =Inputs!$D$11*Inputs!$D$19*1000 -> 203 | D8: =Inputs!$E$11*Inputs!$E$19*1000 -> 360 | E8: =Inputs!$F$11*Inputs!$F$19*1000 -> 640 | F8: =Inputs!$G$11*Inputs!$G$19*1000 -> 360
A9: Paid developer seats | B9: M | C9: =Inputs!$D$6*Inputs!$D$13 -> 23.12 | D9: =Inputs!$E$6*Inputs!$E$13 -> 30.4 | E9: =Inputs!$F$6*Inputs!$F$13 -> 39.6 | F9: =Inputs!$G$6*Inputs!$G$13 -> 30.4 | G9: workers x penetration
A10: Paid professional seats | B10: M | C10: =Inputs!$D$7*Inputs!$D$14 -> 65.6 | D10: =Inputs!$E$7*Inputs!$E$14 -> 99 | E10: =Inputs!$F$7*Inputs!$F$14 -> 132 | F10: =Inputs!$G$7*Inputs!$G$14 -> 99
A11: Paid general KW seats | B11: M | C11: =Inputs!$D$8*Inputs!$D$15 -> 107.8 | D11: =Inputs!$E$8*Inputs!$E$15 -> 197.5 | E11: =Inputs!$F$8*Inputs!$F$15 -> 309.7 | F11: =Inputs!$G$8*Inputs!$G$15 -> 197.5
A12: Developer AI spend pool | B12: $B | C12: =C9*C6/1000 -> 116.5248 | D12: =D9*D6/1000 -> 296.4 | E12: =E9*E6/1000 -> 506.88 | F12: =F9*F6/1000 -> 296.4 | G12: seats (M) x $/seat / 1000
A13: Professional AI spend pool | B13: $B | C13: =C10*C7/1000 -> 56.088 | D13: =D10*D7/1000 -> 178.2 | E13: =E10*E7/1000 -> 386.1 | F13: =F10*F7/1000 -> 178.2
A14: General KW AI spend pool | B14: $B | C14: =C11*C8/1000 -> 21.8834 | D14: =D11*D8/1000 -> 71.1 | E14: =E11*E8/1000 -> 198.208 | F14: =F11*F8/1000 -> 71.1
A15: Machine / agent API pool | B15: $B | C15: =Inputs!$D$28*Inputs!$D$29*Inputs!$D$30*1000 -> 84 | D15: =Inputs!$E$28*Inputs!$E$29*Inputs!$E$30*1000 -> 200 | E15: =Inputs!$F$28*Inputs!$F$29*Inputs!$F$30*1000 -> 420 | F15: =Inputs!$G$28*Inputs!$G$29*Inputs!$G$30*1000 -> 200 | G15: labour pool ($T) x automated share x vendor capture
A16: Total enterprise AI pool (all vendors) | B16: $B | C16: =SUM(C12:C15) -> 278.4962 | D16: =SUM(D12:D15) -> 745.7 | E16: =SUM(E12:E15) -> 1511.188 | F16: =SUM(F12:F15) -> 745.7
A18: OpenAI revenue 2030 by segment
A19: Developers / coding agents | B19: $B | C19: =C12*Inputs!$D$22 -> 20.974464 | D19: =D12*Inputs!$E$22 -> 74.1 | E19: =E12*Inputs!$F$22 -> 162.2016 | F19: =F12*Inputs!$G$22 -> 74.1 | G19: pool x company share
A20: Professional seats | B20: $B | C20: =C13*Inputs!$D$24 -> 14.022 | D20: =D13*Inputs!$E$24 -> 53.46 | E20: =E13*Inputs!$F$24 -> 135.135 | F20: =F13*Inputs!$G$24 -> 53.46
A21: General KW seats | B21: $B | C21: =C14*Inputs!$D$26 -> 4.37668 | D21: =D14*Inputs!$E$26 -> 17.775 | E21: =E14*Inputs!$F$26 -> 59.4624 | F21: =F14*Inputs!$G$26 -> 17.775
A22: Machine / agent API | B22: $B | C22: =C15*Inputs!$D$32 -> 16.8 | D22: =D15*Inputs!$E$32 -> 50 | E22: =E15*Inputs!$F$32 -> 117.6 | F22: =F15*Inputs!$G$32 -> 50
A23: Consumer subscriptions | B23: $B | C23: =Inputs!$D$34*Inputs!$D$35*Inputs!$D$36*12/1000 -> 12.15 | D23: =Inputs!$E$34*Inputs!$E$35*Inputs!$E$36*12/1000 -> 25.92 | E23: =Inputs!$F$34*Inputs!$F$35*Inputs!$F$36*12/1000 -> 64.8 | F23: =Inputs!$G$34*Inputs!$G$35*Inputs!$G$36*12/1000 -> 25.92 | G23: MAU x paid conversion x ARPU x 12
A24: Consumer ads | B24: $B | C24: =Inputs!$D$34*(1-Inputs!$D$35)*Inputs!$D$37/1000 -> 21.4875 | D24: =Inputs!$E$34*(1-Inputs!$E$35)*Inputs!$E$37/1000 -> 56.4 | E24: =Inputs!$F$34*(1-Inputs!$F$35)*Inputs!$F$37/1000 -> 125.125 | F24: =Inputs!$G$34*(1-Inputs!$G$35)*Inputs!$G$37/1000 -> 56.4 | G24: free MAU x ads ARPU
A25: Commerce / agentic transactions | B25: $B | C25: =Inputs!$D$38*Inputs!$D$39 -> 2 | D25: =Inputs!$E$38*Inputs!$E$39 -> 10 | E25: =Inputs!$F$38*Inputs!$F$39 -> 30 | F25: =Inputs!$G$38*Inputs!$G$39 -> 10 | G25: GMV x take rate
A26: Other | B26: $B | C26: =Inputs!$D$45 -> 4 | D26: =Inputs!$E$45 -> 10 | E26: =Inputs!$F$45 -> 20 | F26: =Inputs!$G$45 -> 10
A27: TOTAL REVENUE 2030 | B27: $B | C27: =SUM(C19:C26) -> 95.810644 | D27: =SUM(D19:D26) -> 297.655 | E27: =SUM(E19:E26) -> 714.324 | F27: =SUM(F19:F26) -> 297.655
A28: Enterprise subtotal (4 engines) | B28: $B | C28: =SUM(C19:C22) -> 56.173144 | D28: =SUM(D19:D22) -> 195.335 | E28: =SUM(E19:E22) -> 474.399 | F28: =SUM(F19:F22) -> 195.335
A29: Consumer subtotal | B29: $B | C29: =SUM(C23:C25) -> 35.6375 | D29: =SUM(D23:D25) -> 92.32 | E29: =SUM(E23:E25) -> 219.925 | F29: =SUM(F23:F25) -> 92.32
A30: Enterprise share of revenue | B30: % | C30: =IF(C27=0,0,C28/C27) -> 0.58629336 | D30: =IF(D27=0,0,D28/D27) -> 0.65624633 | E30: =IF(E27=0,0,E28/E27) -> 0.664123 | F30: =IF(F27=0,0,F28/F27) -> 0.65624633
A32: Supply-side check (compute)
A33: GW online (avg 2030) | B33: GW | C33: =Inputs!$D$48 -> 15 | D33: =Inputs!$E$48 -> 22 | E33: =Inputs!$F$48 -> 30 | F33: =Inputs!$G$48 -> 22
A34: Revenue per GW of inference | B34: $B/GW | C34: =Inputs!$D$52*Inputs!$D$53*Inputs!$D$51 -> 11.52 | D34: =Inputs!$E$52*Inputs!$E$53*Inputs!$E$51 -> 21.76 | E34: =Inputs!$F$52*Inputs!$F$53*Inputs!$F$51 -> 64.896 | F34: =Inputs!$G$52*Inputs!$G$53*Inputs!$G$51 -> 21.76 | G34: tokens/GW (1e15) x $/M tokens x utilisation
A35: Revenue per GW of TOTAL capacity | B35: $B/GW | C35: =C34*Inputs!$D$50 -> 6.336 | D35: =D34*Inputs!$E$50 -> 13.4912 | E35: =E34*Inputs!$F$50 -> 46.72512 | F35: =F34*Inputs!$G$50 -> 13.4912 | G35: x inference share of fleet
A36: Supply-side revenue capacity | B36: $B | C36: =C33*C35 -> 95.04 | D36: =D33*D35 -> 296.8064 | E36: =E33*E35 -> 1401.7536 | F36: =F33*F35 -> 296.8064 | G36: GW x $/GW
A37: Demand-side revenue (bottom-up) | B37: $B | C37: =C27 -> 95.810644 | D37: =D27 -> 297.655 | E37: =E27 -> 714.324 | F37: =F27 -> 297.655
A38: Demand / supply capacity | B38: x | C38: =IF(C36=0,0,C37/C36) -> 1.0081086 | D38: =IF(D36=0,0,D37/D36) -> 1.0028591 | E38: =IF(E36=0,0,E37/E36) -> 0.50959313 | F38: =IF(F36=0,0,F37/F36) -> 1.0028591 | G38: >1.0x = compute-constrained
A39: GW needed for demand at this $/GW | B39: GW | C39: =IF(C35=0,0,C37/C35) -> 15.121629 | D39: =IF(D35=0,0,D37/D35) -> 22.0629 | E39: =IF(E35=0,0,E37/E35) -> 15.287794 | F39: =IF(F35=0,0,F37/F35) -> 22.0629
A40: $/GW needed for demand at this GW | B40: $B/GW | C40: =IF(C33=0,0,C37/C33) -> 6.3873763 | D40: =IF(D33=0,0,D37/D33) -> 13.529773 | E40: =IF(E33=0,0,E37/E33) -> 23.8108 | F40: =IF(F33=0,0,F37/F33) -> 13.529773
A42: Momentum path (annualised run-rate)
A43: Exit-2026 run-rate | B43: $B | C43: =Inputs!$D$55 -> 46 | D43: =Inputs!$E$55 -> 50 | E43: =Inputs!$F$55 -> 55 | F43: =Inputs!$G$55 -> 50
A44: Exit-2027 run-rate | B44: $B | C44: =C43*(1+Inputs!$D$57) -> 66.7 | D44: =D43*(1+Inputs!$E$57) -> 87.5 | E44: =E43*(1+Inputs!$F$57) -> 107.25 | F44: =F43*(1+Inputs!$G$57) -> 87.5 | G44: x (1 + growth 2027)
...

Sheet Anthropic
A1: Anthropic - 2030 revenue, bottom-up ($B unless stated)
A2: Green = link to Inputs; black = formula; blue = hardcoded (2026 mix estimates, targets, constants).
A4: Line | B4: Unit | C4: Bear | D4: Base | E4: Bull | F4: Custom | G4: Formula / note
A5: Global pools (all vendors) - shared with the other company
A6: Spend per paid seat - developers | B6: $/yr | C6: =Inputs!$D$9*Inputs!$D$17*1000 -> 5040 | D6: =Inputs!$E$9*Inputs!$E$17*1000 -> 9750 | E6: =Inputs!$F$9*Inputs!$F$17*1000 -> 12800 | F6: =Inputs!$G$9*Inputs!$G$17*1000 -> 9750 | G6: salary x AI spend ratio
A7: Spend per paid seat - professionals | B7: $/yr | C7: =Inputs!$D$10*Inputs!$D$18*1000 -> 855 | D7: =Inputs!$E$10*Inputs!$E$18*1000 -> 1800 | E7: =Inputs!$F$10*Inputs!$F$18*1000 -> 2925 | F7: =Inputs!$G$10*Inputs!$G$18*1000 -> 1800
A8: Spend per paid seat - general KW | B8: $/yr | C8: =Inputs!$D$11*Inputs!$D$19*1000 -> 203 | D8: =Inputs!$E$11*Inputs!$E$19*1000 -> 360 | E8: =Inputs!$F$11*Inputs!$F$19*1000 -> 640 | F8: =Inputs!$G$11*Inputs!$G$19*1000 -> 360
A9: Paid developer seats | B9: M | C9: =Inputs!$D$6*Inputs!$D$13 -> 23.12 | D9: =Inputs!$E$6*Inputs!$E$13 -> 30.4 | E9: =Inputs!$F$6*Inputs!$F$13 -> 39.6 | F9: =Inputs!$G$6*Inputs!$G$13 -> 30.4 | G9: workers x penetration
A10: Paid professional seats | B10: M | C10: =Inputs!$D$7*Inputs!$D$14 -> 65.6 | D10: =Inputs!$E$7*Inputs!$E$14 -> 99 | E10: =Inputs!$F$7*Inputs!$F$14 -> 132 | F10: =Inputs!$G$7*Inputs!$G$14 -> 99
A11: Paid general KW seats | B11: M | C11: =Inputs!$D$8*Inputs!$D$15 -> 107.8 | D11: =Inputs!$E$8*Inputs!$E$15 -> 197.5 | E11: =Inputs!$F$8*Inputs!$F$15 -> 309.7 | F11: =Inputs!$G$8*Inputs!$G$15 -> 197.5
A12: Developer AI spend pool | B12: $B | C12: =C9*C6/1000 -> 116.5248 | D12: =D9*D6/1000 -> 296.4 | E12: =E9*E6/1000 -> 506.88 | F12: =F9*F6/1000 -> 296.4 | G12: seats (M) x $/seat / 1000
A13: Professional AI spend pool | B13: $B | C13: =C10*C7/1000 -> 56.088 | D13: =D10*D7/1000 -> 178.2 | E13: =E10*E7/1000 -> 386.1 | F13: =F10*F7/1000 -> 178.2
A14: General KW AI spend pool | B14: $B | C14: =C11*C8/1000 -> 21.8834 | D14: =D11*D8/1000 -> 71.1 | E14: =E11*E8/1000 -> 198.208 | F14: =F11*F8/1000 -> 71.1
A15: Machine / agent API pool | B15: $B | C15: =Inputs!$D$28*Inputs!$D$29*Inputs!$D$30*1000 -> 84 | D15: =Inputs!$E$28*Inputs!$E$29*Inputs!$E$30*1000 -> 200 | E15: =Inputs!$F$28*Inputs!$F$29*Inputs!$F$30*1000 -> 420 | F15: =Inputs!$G$28*Inputs!$G$29*Inputs!$G$30*1000 -> 200 | G15: labour pool ($T) x automated share x vendor capture
A16: Total enterprise AI pool (all vendors) | B16: $B | C16: =SUM(C12:C15) -> 278.4962 | D16: =SUM(D12:D15) -> 745.7 | E16: =SUM(E12:E15) -> 1511.188 | F16: =SUM(F12:F15) -> 745.7
A18: Anthropic revenue 2030 by segment
A19: Developers / coding agents | B19: $B | C19: =C12*Inputs!$D$21 -> 40.78368 | D19: =D12*Inputs!$E$21 -> 124.488 | E19: =E12*Inputs!$F$21 -> 243.3024 | F19: =F12*Inputs!$G$21 -> 124.488 | G19: pool x company share
A20: Professional seats | B20: $B | C20: =C13*Inputs!$D$23 -> 7.29144 | D20: =D13*Inputs!$E$23 -> 35.64 | E20: =E13*Inputs!$F$23 -> 92.664 | F20: =F13*Inputs!$G$23 -> 35.64
A21: General KW seats | B21: $B | C21: =C14*Inputs!$D$25 -> 1.313004 | D21: =D14*Inputs!$E$25 -> 5.688 | E21: =E14*Inputs!$F$25 -> 23.78496 | F21: =F14*Inputs!$G$25 -> 5.688
A22: Machine / agent API | B22: $B | C22: =C15*Inputs!$D$31 -> 25.2 | D22: =D15*Inputs!$E$31 -> 76 | E22: =E15*Inputs!$F$31 -> 168 | F22: =F15*Inputs!$G$31 -> 76
A23: Consumer subscriptions | B23: $B | C23: =Inputs!$D$41*Inputs!$D$42*Inputs!$D$43*12/1000 -> 3.744 | D23: =Inputs!$E$41*Inputs!$E$42*Inputs!$E$43*12/1000 -> 9.6 | E23: =Inputs!$F$41*Inputs!$F$42*Inputs!$F$43*12/1000 -> 24.96 | F23: =Inputs!$G$41*Inputs!$G$42*Inputs!$G$43*12/1000 -> 9.6 | G23: MAU x paid conversion x ARPU x 12
A24: Consumer ads | B24: $B | C24: =0 -> 0 | D24: =0 -> 0 | E24: =0 -> 0 | F24: =0 -> 0 | G24: Anthropic: no ads (stated policy) - hardcoded 0
A25: Commerce / agentic transactions | B25: $B | C25: =0 -> 0 | D25: =0 -> 0 | E25: =0 -> 0 | F25: =0 -> 0 | G25: not modelled - hardcoded 0
A26: Other | B26: $B | C26: =Inputs!$D$46 -> 4 | D26: =Inputs!$E$46 -> 8 | E26: =Inputs!$F$46 -> 15 | F26: =Inputs!$G$46 -> 8
A27: TOTAL REVENUE 2030 | B27: $B | C27: =SUM(C19:C26) -> 82.332124 | D27: =SUM(D19:D26) -> 259.416 | E27: =SUM(E19:E26) -> 567.71136 | F27: =SUM(F19:F26) -> 259.416
A28: Enterprise subtotal (4 engines) | B28: $B | C28: =SUM(C19:C22) -> 74.588124 | D28: =SUM(D19:D22) -> 241.816 | E28: =SUM(E19:E22) -> 527.75136 | F28: =SUM(F19:F22) -> 241.816
A29: Consumer subtotal | B29: $B | C29: =SUM(C23:C25) -> 3.744 | D29: =SUM(D23:D25) -> 9.6 | E29: =SUM(E23:E25) -> 24.96 | F29: =SUM(F23:F25) -> 9.6
A30: Enterprise share of revenue | B30: % | C30: =IF(C27=0,0,C28/C27) -> 0.90594194 | D30: =IF(D27=0,0,D28/D27) -> 0.9321553 | E30: =IF(E27=0,0,E28/E27) -> 0.92961212 | F30: =IF(F27=0,0,F28/F27) -> 0.9321553
A32: Supply-side check (compute)
A33: GW online (avg 2030) | B33: GW | C33: =Inputs!$D$49 -> 10 | D33: =Inputs!$E$49 -> 16 | E33: =Inputs!$F$49 -> 22 | F33: =Inputs!$G$49 -> 16
A34: Revenue per GW of inference | B34: $B/GW | C34: =Inputs!$D$52*Inputs!$D$53*Inputs!$D$51 -> 11.52 | D34: =Inputs!$E$52*Inputs!$E$53*Inputs!$E$51 -> 21.76 | E34: =Inputs!$F$52*Inputs!$F$53*Inputs!$F$51 -> 64.896 | F34: =Inputs!$G$52*Inputs!$G$53*Inputs!$G$51 -> 21.76 | G34: tokens/GW (1e15) x $/M tokens x utilisation
A35: Revenue per GW of TOTAL capacity | B35: $B/GW | C35: =C34*Inputs!$D$50 -> 6.336 | D35: =D34*Inputs!$E$50 -> 13.4912 | E35: =E34*Inputs!$F$50 -> 46.72512 | F35: =F34*Inputs!$G$50 -> 13.4912 | G35: x inference share of fleet
A36: Supply-side revenue capacity | B36: $B | C36: =C33*C35 -> 63.36 | D36: =D33*D35 -> 215.8592 | E36: =E33*E35 -> 1027.9526 | F36: =F33*F35 -> 215.8592 | G36: GW x $/GW
A37: Demand-side revenue (bottom-up) | B37: $B | C37: =C27 -> 82.332124 | D37: =D27 -> 259.416 | E37: =E27 -> 567.71136 | F37: =F27 -> 259.416
A38: Demand / supply capacity | B38: x | C38: =IF(C36=0,0,C37/C36) -> 1.2994338 | D38: =IF(D36=0,0,D37/D36) -> 1.2017834 | E38: =IF(E36=0,0,E37/E36) -> 0.55227385 | F38: =IF(F36=0,0,F37/F36) -> 1.2017834 | G38: >1.0x = compute-constrained
A39: GW needed for demand at this $/GW | B39: GW | C39: =IF(C35=0,0,C37/C35) -> 12.994338 | D39: =IF(D35=0,0,D37/D35) -> 19.228534 | E39: =IF(E35=0,0,E37/E35) -> 12.150025 | F39: =IF(F35=0,0,F37/F35) -> 19.228534
A40: $/GW needed for demand at this GW | B40: $B/GW | C40: =IF(C33=0,0,C37/C33) -> 8.2332124 | D40: =IF(D33=0,0,D37/D33) -> 16.2135 | E40: =IF(E33=0,0,E37/E33) -> 25.805062 | F40: =IF(F33=0,0,F37/F33) -> 16.2135
A42: Momentum path (annualised run-rate)
A43: Exit-2026 run-rate | B43: $B | C43: =Inputs!$D$56 -> 80 | D43: =Inputs!$E$56 -> 90 | E43: =Inputs!$F$56 -> 100 | F43: =Inputs!$G$56 -> 90
A44: Exit-2027 run-rate | B44: $B | C44: =C43*(1+Inputs!$D$61) -> 112 | D44: =D43*(1+Inputs!$E$61) -> 153 | E44: =E43*(1+Inputs!$F$61) -> 200 | F44: =F43*(1+Inputs!$G$61) -> 153 | G44: x (1 + growth 2027)
...

Sheet Sensitivity
A1: Two-way sensitivities (all constants read the Base column of Inputs; headers in blue are editable)
A3: Revenue ($B) = GW x $/GW
A4: GW \ $B/GW | B4: 8 | C4: 10.5 | D4: 14 | E4: 20 | F4: 28 | G4: 35
A5: 10 | B5: =$A5*B$4 -> 80 | C5: =$A5*C$4 -> 105 | D5: =$A5*D$4 -> 140 | E5: =$A5*E$4 -> 200 | F5: =$A5*F$4 -> 280 | G5: =$A5*G$4 -> 350
A6: 15 | B6: =$A6*B$4 -> 120 | C6: =$A6*C$4 -> 157.5 | D6: =$A6*D$4 -> 210 | E6: =$A6*E$4 -> 300 | F6: =$A6*F$4 -> 420 | G6: =$A6*G$4 -> 525
A7: 20 | B7: =$A7*B$4 -> 160 | C7: =$A7*C$4 -> 210 | D7: =$A7*D$4 -> 280 | E7: =$A7*E$4 -> 400 | F7: =$A7*F$4 -> 560 | G7: =$A7*G$4 -> 700
A8: 25 | B8: =$A8*B$4 -> 200 | C8: =$A8*C$4 -> 262.5 | D8: =$A8*D$4 -> 350 | E8: =$A8*E$4 -> 500 | F8: =$A8*F$4 -> 700 | G8: =$A8*G$4 -> 875
A9: 30 | B9: =$A9*B$4 -> 240 | C9: =$A9*C$4 -> 315 | D9: =$A9*D$4 -> 420 | E9: =$A9*E$4 -> 600 | F9: =$A9*F$4 -> 840 | G9: =$A9*G$4 -> 1050
A11: $/GW of TOTAL capacity ($B) = tokens/GW (1e15) x $/M tokens x inference share x utilisation (Base)
A12: q tokens/GW-yr \ $/M tokens | B12: 0.8 | C12: 1.2 | D12: 1.6 | E12: 2.2 | F12: 3
A13: 12 | B13: =$A13*B$12*Inputs!$E$50*Inputs!$E$51 -> 4.04736 | C13: =$A13*C$12*Inputs!$E$50*Inputs!$E$51 -> 6.07104 | D13: =$A13*D$12*Inputs!$E$50*Inputs!$E$51 -> 8.09472 | E13: =$A13*E$12*Inputs!$E$50*Inputs!$E$51 -> 11.13024 | F13: =$A13*F$12*Inputs!$E$50*Inputs!$E$51 -> 15.1776
A14: 16 | B14: =$A14*B$12*Inputs!$E$50*Inputs!$E$51 -> 5.39648 | C14: =$A14*C$12*Inputs!$E$50*Inputs!$E$51 -> 8.09472 | D14: =$A14*D$12*Inputs!$E$50*Inputs!$E$51 -> 10.79296 | E14: =$A14*E$12*Inputs!$E$50*Inputs!$E$51 -> 14.84032 | F14: =$A14*F$12*Inputs!$E$50*Inputs!$E$51 -> 20.2368
A15: 20 | B15: =$A15*B$12*Inputs!$E$50*Inputs!$E$51 -> 6.7456 | C15: =$A15*C$12*Inputs!$E$50*Inputs!$E$51 -> 10.1184 | D15: =$A15*D$12*Inputs!$E$50*Inputs!$E$51 -> 13.4912 | E15: =$A15*E$12*Inputs!$E$50*Inputs!$E$51 -> 18.5504 | F15: =$A15*F$12*Inputs!$E$50*Inputs!$E$51 -> 25.296
A16: 24 | B16: =$A16*B$12*Inputs!$E$50*Inputs!$E$51 -> 8.09472 | C16: =$A16*C$12*Inputs!$E$50*Inputs!$E$51 -> 12.14208 | D16: =$A16*D$12*Inputs!$E$50*Inputs!$E$51 -> 16.18944 | E16: =$A16*E$12*Inputs!$E$50*Inputs!$E$51 -> 22.26048 | F16: =$A16*F$12*Inputs!$E$50*Inputs!$E$51 -> 30.3552
A17: 32 | B17: =$A17*B$12*Inputs!$E$50*Inputs!$E$51 -> 10.79296 | C17: =$A17*C$12*Inputs!$E$50*Inputs!$E$51 -> 16.18944 | D17: =$A17*D$12*Inputs!$E$50*Inputs!$E$51 -> 21.58592 | E17: =$A17*E$12*Inputs!$E$50*Inputs!$E$51 -> 29.68064 | F17: =$A17*F$12*Inputs!$E$50*Inputs!$E$51 -> 40.4736
A19: OpenAI ads revenue ($B) = free MAU (M) x ads ARPU ($/yr)
A20: free MAU (M) \ $/free user/yr | B20: 15 | C20: 30 | D20: 45 | E20: 60 | F20: 80
A21: 1400 | B21: =$A21*B$20/1000 -> 21 | C21: =$A21*C$20/1000 -> 42 | D21: =$A21*D$20/1000 -> 63 | E21: =$A21*E$20/1000 -> 84 | F21: =$A21*F$20/1000 -> 112
A22: 1900 | B22: =$A22*B$20/1000 -> 28.5 | C22: =$A22*C$20/1000 -> 57 | D22: =$A22*D$20/1000 -> 85.5 | E22: =$A22*E$20/1000 -> 114 | F22: =$A22*F$20/1000 -> 152
A23: 2300 | B23: =$A23*B$20/1000 -> 34.5 | C23: =$A23*C$20/1000 -> 69 | D23: =$A23*D$20/1000 -> 103.5 | E23: =$A23*E$20/1000 -> 138 | F23: =$A23*F$20/1000 -> 184
A25: OpenAI consumer subscriptions ($B) = MAU (M) x paid conversion x Base ARPU x 12
A26: MAU (M) \ paid conversion | B26: 0.04 | C26: 0.06 | D26: 0.08 | E26: 0.1
A27: 1500 | B27: =$A27*B$26*Inputs!$E$36*12/1000 -> 12.96 | C27: =$A27*C$26*Inputs!$E$36*12/1000 -> 19.44 | D27: =$A27*D$26*Inputs!$E$36*12/1000 -> 25.92 | E27: =$A27*E$26*Inputs!$E$36*12/1000 -> 32.4
A28: 2000 | B28: =$A28*B$26*Inputs!$E$36*12/1000 -> 17.28 | C28: =$A28*C$26*Inputs!$E$36*12/1000 -> 25.92 | D28: =$A28*D$26*Inputs!$E$36*12/1000 -> 34.56 | E28: =$A28*E$26*Inputs!$E$36*12/1000 -> 43.2
A29: 2500 | B29: =$A29*B$26*Inputs!$E$36*12/1000 -> 21.6 | C29: =$A29*C$26*Inputs!$E$36*12/1000 -> 32.4 | D29: =$A29*D$26*Inputs!$E$36*12/1000 -> 43.2 | E29: =$A29*E$26*Inputs!$E$36*12/1000 -> 54
A31: Anthropic developer engine ($B) = paid devs (Base: workers x penetration) x spend ($k/dev/yr) x Anthropic share
A32: $k/dev/yr \ Anthropic share | B32: 0.3 | C32: 0.36 | D32: 0.42 | E32: 0.48
A33: 4 | B33: =Inputs!$E$6*Inputs!$E$13*$A33*B$32 -> 36.48 | C33: =Inputs!$E$6*Inputs!$E$13*$A33*C$32 -> 43.776 | D33: =Inputs!$E$6*Inputs!$E$13*$A33*D$32 -> 51.072 | E33: =Inputs!$E$6*Inputs!$E$13*$A33*E$32 -> 58.368
A34: 6 | B34: =Inputs!$E$6*Inputs!$E$13*$A34*B$32 -> 54.72 | C34: =Inputs!$E$6*Inputs!$E$13*$A34*C$32 -> 65.664 | D34: =Inputs!$E$6*Inputs!$E$13*$A34*D$32 -> 76.608 | E34: =Inputs!$E$6*Inputs!$E$13*$A34*E$32 -> 87.552
A35: 9 | B35: =Inputs!$E$6*Inputs!$E$13*$A35*B$32 -> 82.08 | C35: =Inputs!$E$6*Inputs!$E$13*$A35*C$32 -> 98.496 | D35: =Inputs!$E$6*Inputs!$E$13*$A35*D$32 -> 114.912 | E35: =Inputs!$E$6*Inputs!$E$13*$A35*E$32 -> 131.328
A36: 12 | B36: =Inputs!$E$6*Inputs!$E$13*$A36*B$32 -> 109.44 | C36: =Inputs!$E$6*Inputs!$E$13*$A36*C$32 -> 131.328 | D36: =Inputs!$E$6*Inputs!$E$13*$A36*D$32 -> 153.216 | E36: =Inputs!$E$6*Inputs!$E$13*$A36*E$32 -> 175.104
A37: 15 | B37: =Inputs!$E$6*Inputs!$E$13*$A37*B$32 -> 136.8 | C37: =Inputs!$E$6*Inputs!$E$13*$A37*C$32 -> 164.16 | D37: =Inputs!$E$6*Inputs!$E$13*$A37*D$32 -> 191.52 | E37: =Inputs!$E$6*Inputs!$E$13*$A37*E$32 -> 218.88
A39: Professional-seat global pool ($B) = professionals (Base) x penetration x $/seat
A40: penetration \ $/seat/yr | B40: 900 | C40: 1800 | D40: 2700 | E40: 3600
A41: 0.3 | B41: =Inputs!$E$7*$A41*B$40/1000 -> 59.4 | C41: =Inputs!$E$7*$A41*C$40/1000 -> 118.8 | D41: =Inputs!$E$7*$A41*D$40/1000 -> 178.2 | E41: =Inputs!$E$7*$A41*E$40/1000 -> 237.6
A42: 0.45 | B42: =Inputs!$E$7*$A42*B$40/1000 -> 89.1 | C42: =Inputs!$E$7*$A42*C$40/1000 -> 178.2 | D42: =Inputs!$E$7*$A42*D$40/1000 -> 267.3 | E42: =Inputs!$E$7*$A42*E$40/1000 -> 356.4
A43: 0.6 | B43: =Inputs!$E$7*$A43*B$40/1000 -> 118.8 | C43: =Inputs!$E$7*$A43*C$40/1000 -> 237.6 | D43: =Inputs!$E$7*$A43*D$40/1000 -> 356.4 | E43: =Inputs!$E$7*$A43*E$40/1000 -> 475.2
A45: Machine / agent API global pool ($B) = labour pool (Base, $T) x automated share x vendor capture
A46: automated share \ vendor capture | B46: 0.15 | C46: 0.2 | D46: 0.25 | E46: 0.3 | F46: 0.35
A47: 0.05 | B47: =Inputs!$E$28*1000*$A47*B$46 -> 60 | C47: =Inputs!$E$28*1000*$A47*C$46 -> 80 | D47: =Inputs!$E$28*1000*$A47*D$46 -> 100 | E47: =Inputs!$E$28*1000*$A47*E$46 -> 120 | F47: =Inputs!$E$28*1000*$A47*F$46 -> 140
...

Sheet Sources
A1: Data anchors and sources (as of 24-Sep-2026; several are press summaries of company disclosures - flagged 'secondary')
A3: Data point | B3: Date | C3: Source | D3: URL
A4: OpenAI annualised revenue run-rate >$40B; enterprise >50% of mix | B4: Aug-2026 | C4: press (enterprisedna.co / valueaddvc.com summaries of company statements) | D4: https://enterprisedna.co/resources/news/openai-enterprise-revenue-overtakes-consumer-40-billion-arr-2026/
A5: ChatGPT ~1B MAU (Jun-26), ~1B WAU (Jul-26); >50M consumer subs; 9M paying business users; 7M enterprise seats | B5: Jul/Aug-2026 | C5: demandsage / secondtalent (secondary) | D5: https://www.demandsage.com/chatgpt-statistics/
A6: OpenAI forecasts 2030 revenue >$280B; consumer/enterprise ~50/50 by 2030 | B6: 20-Feb-2026 | C6: Bloomberg | D6: https://www.bloomberg.com/news/articles/2026-02-20/openai-forecasts-its-revenue-will-top-280-billion-in-2030
A7: OpenAI ads plan: $2.5B 2026, $11B 2027, $25B 2028, $53B 2029, $100B 2030 | B7: 09-Apr-2026 | C7: Axios | D7: https://axios.com/2026/04/09/openai-100-billion-in-ad-revenue
A8: ChatGPT ads: launched 9-Feb-2026 (US Free + Go); $1B run-rate in <200 days; ~$60 CPM | B8: 2026 | C8: press (secondary) | D8: https://explainx.ai/blog/openai-advertise-in-chatgpt-ads-launch-july-2026
A9: OpenAI API 15B tokens/min; Codex 2M+ weekly users | B9: Mar-2026 | C9: OpenAI | D9: https://openai.com/index/a-business-that-scales-with-the-value-of-intelligence/
A10: OpenAI compute: 0.2GW (2023) -> 1.9GW (2025) while run-rate $2B -> $20B (~$10B/GW) | B10: 2025 | C10: MBI Deep Dives citing OpenAI | D10: https://www.mbi-deepdives.com/oai-breakeven/
A11: OpenAI 30GW target by 2030; compute spend ~$600B -> ~$750B through 2030 | B11: 2026 | C11: WSJ / DCD (secondary) | D11: https://www.datacenterdynamics.com/en/news/openai-cuts-projected-compute-spend-to-600bn-by-2030-report/
A12: OpenAI-Nvidia 10GW LOI; AMD 6GW; Broadcom 10GW; Stargate 10GW (8GW+ secured) | B12: 2025-26 | C12: OpenAI | D12: https://openai.com/index/openai-nvidia-systems-partnership/
A13: Oracle-OpenAI $300B / 5 yrs / 4.5GW (~$13.3B per GW-year) | B13: Jul/Sep-2025 | C13: The Register | D13: https://www.theregister.com/2025/07/22/openai_oracle_gpus/
A14: Anthropic run-rate $65B (end-Jul-26); $47B mid-May; $9B end-2025 | B14: 17-Aug-2026 | C14: Bloomberg / TechCrunch / Axios | D14: https://techcrunch.com/2026/08/17/anthropics-annualized-revenue-surges-to-65b/
... A35: Superforecasters: OpenAI+Anthropic combined 2030 run-rate median $300B; 34% prob >$400B; 18% prob <$100B | B35: 2026 | C35: Forecasting Research Institute | D35: https://forecastingresearch.substack.com/p/will-the-ai-boom-continue-forecasting
